<?xml version="1.0" ?>
<!-- =================================================================================== -->
<!-- |    This document was autogenerated by xacro from ada_lovelace.xacro.urdf        | -->
<!-- |    EDITING THIS FILE BY HAND IS NOT RECOMMENDED                                 | -->
<!-- =================================================================================== -->
<robot name="ada_lovelace">
  <!-- LINKS -->
  <link name="base_footprint_link"/>
  <link name="base_link">
    <visual>
      <geometry>
        <cylinder length="0.08" radius="0.175"/>
      </geometry>
      <origin rpy="0 0 0" xyz="0 0 0"/>
      <material name="white">
        <color rgba="1 1 1 1"/>
      </material>
    </visual>
    <collision>
      <geometry>
        <cylinder length="0.08" radius="0.175"/>
      </geometry>
      <origin rpy="0 0 0" xyz="0 0 0"/>
    </collision>
    <inertial>
      <origin rpy="0 0 0" xyz="0 0 0"/>
      <mass value="4.2"/>
      <inertia ixx="0.03439625" ixy="0" ixz="0" iyy="0.03439625" iyz="0" izz="0.0643125"/>
    </inertial>
  </link>
  <link name="lidar_link">
    <visual>
      <geometry>
        <cylinder length="0.03" radius="0.035"/>
      </geometry>
      <origin rpy="0 0 0" xyz="0 0 0"/>
      <material name="red">
        <color rgba="1 0 0 1"/>
      </material>
    </visual>
    <collision>
      <geometry>
        <cylinder length="0.03" radius="0.035"/>
      </geometry>
      <origin rpy="0 0 0" xyz="0 0 0"/>
    </collision>
    <inertial>
      <origin rpy="0 0 0" xyz="0 0 0"/>
      <mass value="0.20"/>
      <inertia ixx="0.000095" ixy="0" ixz="0" iyy="0.000095" iyz="0" izz="0.00032"/>
    </inertial>
  </link>
  <link name="left_wheel_link">
    <visual>
      <geometry>
        <cylinder length="0.02" radius="0.04"/>
      </geometry>
      <origin rpy="0 0 0" xyz="0 0 0"/>
      <material name="blue">
        <color rgba="0.1 0.1 0.8 1"/>
      </material>
    </visual>
    <collision>
      <geometry>
        <cylinder length="0.02" radius="0.04"/>
      </geometry>
      <origin rpy="0 0 0" xyz="0 0 0"/>
    </collision>
    <inertial>
      <origin rpy="0 0 0" xyz="0 0 0"/>
      <mass value="0.10"/>
      <inertia ixx="0.00004333" ixy="0" ixz="0" iyy="0.00004333" iyz="0" izz="0.00008"/>
    </inertial>
  </link>
  <link name="right_wheel_link">
    <visual>
      <geometry>
        <cylinder length="0.02" radius="0.04"/>
      </geometry>
      <origin rpy="0 0 0" xyz="0 0 0"/>
      <material name="blue">
        <color rgba="0.1 0.1 0.8 1"/>
      </material>
    </visual>
    <collision>
      <geometry>
        <cylinder length="0.02" radius="0.04"/>
      </geometry>
      <origin rpy="0 0 0" xyz="0 0 0"/>
    </collision>
    <inertial>
      <origin rpy="0 0 0" xyz="0 0 0"/>
      <mass value="0.10"/>
      <inertia ixx="0.00004333" ixy="0" ixz="0" iyy="0.00004333" iyz="0" izz="0.00008"/>
    </inertial>
  </link>
  <link name="front_ball_castor_link">
    <visual>
      <geometry>
        <sphere radius="0.005"/>
      </geometry>
      <origin rpy="0 0 0" xyz="0 0 0"/>
      <material name="blue">
        <color rgba="0.1 0.1 0.8 1"/>
      </material>
    </visual>
    <collision>
      <geometry>
        <sphere radius="0.005"/>
      </geometry>
      <origin rpy="0 0 0" xyz="0 0 0"/>
    </collision>
    <inertial>
      <origin rpy="0 0 0" xyz="0 0 0"/>
      <mass value="0.06"/>
      <inertia ixx="0.00000012" ixy="0" ixz="0" iyy="0.00000012" iyz="0" izz="0.00000012"/>
    </inertial>
  </link>
  <link name="rear_ball_castor_link">
    <visual>
      <geometry>
        <sphere radius="0.005"/>
      </geometry>
      <origin rpy="0 0 0" xyz="0 0 0"/>
      <material name="blue">
        <color rgba="0.1 0.1 0.8 1"/>
      </material>
    </visual>
    <collision>
      <geometry>
        <sphere radius="0.005"/>
      </geometry>
      <origin rpy="0 0 0" xyz="0 0 0"/>
    </collision>
    <inertial>
      <origin rpy="0 0 0" xyz="0 0 0"/>
      <mass value="0.06"/>
      <inertia ixx="0.00000012" ixy="0" ixz="0" iyy="0.00000012" iyz="0" izz="0.00000012"/>
    </inertial>
  </link>
  <link name="imu_link">
        
    </link>
  <link name="chassis_link">

    </link>
  <link name="depth_camera_link">
    <visual>
      <geometry>
        <box size="0.016 0.08 0.016"/>
      </geometry>
      <origin rpy="0 0 0" xyz="0 0 0"/>
      <material name="green">
        <color rgba="0 1 0 1"/>
      </material>
    </visual>
    <collision>
      <geometry>
        <box size="0.016 0.08 0.016"/>
      </geometry>
      <origin rpy="0 0 0" xyz="0 0 0"/>
    </collision>
    <inertial>
      <origin rpy="0 0 0" xyz="0 0 0"/>
      <mass value="0.08"/>
      <inertia ixx="0.00004437" ixy="0" ixz="0" iyy="0.00000034133" iyz="0" izz="0.00004437"/>
    </inertial>
  </link>
  <!-- JOINTS -->
  <joint name="base_footprint_link_base_link_joint" type="fixed">
    <parent link="base_footprint_link"/>
    <child link="base_link"/>
    <origin rpy="0 0 0" xyz="0 0 0.005"/>
  </joint>
  <joint name="base_link_left_wheel_link_joint" type="continuous">
    <parent link="base_link"/>
    <child link="left_wheel_link"/>
    <origin rpy="0 0 0" xyz="0 0.13 0.035"/>
  </joint>
  <joint name="base_link_right_wheel_link_joint" type="continuous">
    <parent link="base_link"/>
    <child link="right_wheel_link"/>
    <origin rpy="0 0 0" xyz="0 -0.13 0.035"/>
  </joint>
  <joint name="base_link_front_ball_castor_link_joint" type="fixed">
    <parent link="base_link"/>
    <child link="front_ball_castor_link"/>
    <origin rpy="0 0 0" xyz="0.145 0 0.005"/>
  </joint>
  <joint name="base_link_rear_ball_castor_link_joint" type="fixed">
    <parent link="base_link"/>
    <child link="rear_ball_castor_link"/>
    <origin rpy="0 0 0" xyz="-0.145 0 0.005"/>
  </joint>
  <joint name="base_link_chassis_link_joint" type="fixed">
    <parent link="base_link"/>
    <child link="chassis_link"/>
    <origin rpy="0 0 0" xyz="0 0 0.045"/>
  </joint>
  <joint name="base_link_depth_camera_link_joint" type="fixed">
    <parent link="base_link"/>
    <child link="depth_camera_link"/>
    <origin rpy="0 0 0" xyz="0.149 0 0.032"/>
  </joint>
  <joint name="base_link_imu_link_joint" type="fixed">
    <parent link="base_link"/>
    <child link="imu_link"/>
    <origin rpy="0 0 0" xyz="0 0 0"/>
  </joint>
  <!-- GAZEBO PLUGINS -->
  <!-- Differential Drive - https://gazebosim.org/api/gazebo/4.5/classignition_1_1gazebo_1_1systems_1_1DiffDrive.html -->
  <gazebo>
    <plugin filename="ignition-gazebo-diff-drive-system" name="ignition::gazebo::systems::DiffDrive">
      <!-- Wheel Joints -->
      <left_joint>base_link_left_wheel_link_joint</left_joint>
      <right_joint>base_link_right_wheel_link_joint</right_joint>
      <!-- Kinematics -->
      <wheel_separation>0.26</wheel_separation>
      <wheel_radius>0.04</wheel_radius>
      <min_linear_velocity>-1.2</min_linear_velocity>
      <max_linear_velocity>1.2</max_linear_velocity>
      <min_angular_velocity>-3.14159</min_angular_velocity>
      <max_angular_velocity>3.14159</max_angular_velocity>
      <odom_publish_frequency>100</odom_publish_frequency>
      <!-- TF Frames -->
      <frame_id>/odom_raw</frame_id>
      <child_frame_id>/base_footprint_link</child_frame_id>
      <!-- topics -->
      <!-- <topic>/model/gz_example_robot/cmd_vel</topic> THIS IS DEFAULT -->
      <odom_topic>/model/ada_lovelace/odometry</odom_topic>
      <!-- <tf_topic>/model/gz_example_robot/tf</tf_topic> THIS IS DEFAULT -->
      <!-- <tf_topic></tf_topic> Leave blank if you plan to use a filter + imu (e.g. EKF) -->
    </plugin>
  </gazebo>
  <gazebo>
    <plugin filename="ignition-gazebo-joint-state-publisher-system" name="ignition::gazebo::systems::JointStatePublisher">
      <update_rate>100</update_rate>
      <joint_name>base_link_left_wheel_link_joint</joint_name>
      <joint_name>base_link_right_wheel_link_joint</joint_name>
    </plugin>
  </gazebo>
  <gazebo reference="front_ball_castor_link">
    <mu1 value="0.001"/>
    <mu2 value="0.001"/>
  </gazebo>
  <gazebo reference="rear_ball_castor_link">
    <mu1 value="0.001"/>
    <mu2 value="0.001"/>
  </gazebo>
  <gazebo reference="right_wheel_link">
    <mu1 value="1.0"/>
    <mu2 value="1.0"/>
  </gazebo>
  <gazebo reference="left_wheel_link">
    <mu1 value="1.0"/>
    <mu2 value="1.0"/>
  </gazebo>
  <gazebo reference="lidar_link">
    <sensor name="generic_lidar_sensor" type="gpu_lidar">
      <topic>/model/ada_lovelace/scan</topic>
      <frame_id>lidar_link</frame_id>
      <ignition_frame_id>lidar_link</ignition_frame_id>
      <update_rate>10.0</update_rate>
      <ray>
        <scan>
          <horizontal>
            <samples>1024</samples>
            <resolution>1</resolution>
            <min_angle>-2.356194490192345</min_angle>
            <max_angle>2.356194490192345</max_angle>
          </horizontal>
        </scan>
        <range>
          <min>0.20</min>
          <max>4.0</max>
          <resolution>0.03</resolution>
        </range>
      </ray>
      <always_on>1</always_on>
      <visualize>false</visualize>
    </sensor>
  </gazebo>
  <gazebo>
    <plugin filename="libignition-gazebo-sensors-system.so" name="ignition::gazebo::systems::Sensors">
      <render_engine>ogre2</render_engine>
    </plugin>
  </gazebo>
  <gazebo reference="imu_link">
    <sensor name="imu_sensor" type="imu">
      <topic>/model/ada_lovelace/imu_raw</topic>
      <frame_id>imu_link</frame_id>
      <ignition_frame_id>imu_link</ignition_frame_id>
      <plugin filename="libignition-gazebo-imu-system.so" name="ignition::gazebo::systems::Imu">
        <initial_orientation_as_reference>false</initial_orientation_as_reference>
      </plugin>
      <always_on>true</always_on>
      <update_rate>100</update_rate>
      <visualize>true</visualize>
    </sensor>
  </gazebo>
  <!-- Gazebo Depth Camera Sensor -->
  <gazebo reference="depth_camera_link">
    <sensor name="depth_camera" type="camera">
      <topic>/model/ada_lovelace/depth</topic>
      <frame_id>depth_camera_link</frame_id>
      <ignition_frame_id>depth_camera_link</ignition_frame_id>
      <update_rate>60</update_rate>
      <camera>
        <horizontal_fov>1.51844</horizontal_fov>
        <!-- Field of view in radians -->
        <vertical_fov>1.01229</vertical_fov>
        <image>
          <width>1280</width>
          <height>720</height>
          <format>R8G8B8</format>
        </image>
        <clip>
          <near>0.3</near>
          <far>4.0</far>
        </clip>
      </camera>
      <always_on>1</always_on>
      <plugin filename="libgazebo_ros_camera.so" name="gazebo_ros_camera">
        <robotNamespace>/ada_lovelace</robotNamespace>
        <imageTopicName>/depth_camera/image_raw</imageTopicName>
        <cameraInfoTopicName>/depth_camera/camera_info</cameraInfoTopicName>
        <frameName>depth</frameName>
      </plugin>
    </sensor>
  </gazebo>
</robot>
