<?xml version="1.0"?>

<robot name="diff_drive_example">

    <!-- Materials -->
    <material name="uom_yellow">
        <color rgba="1.0 0.8 0.2 1"/>
    </material>

    <!-- LINKS -->
    <link name="base_link">
        <visual>
            <geometry>

                <!-- Box is defined as xyz lengths in m -->

                <box size="0.5 0.4 0.3"/>

            </geometry>

            <!-- Centre of box relative to link -->

            <!-- Leave as "0 0 0" for box centre at link origin -->

            <origin xyz="0.15 0 0.10" rpy="0 0 0"/>
        </visual>

        <collision>
            <!-- Same geometry and origin as visuals -->
            <geometry>

                <box size="0.5 0.4 0.3"/>

            </geometry>

            <origin xyz="0.15 0 0.10" rpy="0 0 0"/>

        </collision>

        <inertial>

            <mass value="12"/>

            <inertia ixx="0.25" ixy="0.0" ixz="0.0" iyy="0.34" iyz="0.0" izz="0.41"/>

            <origin xyz="0.15 0 0.10" rpy="0 0 0"/>

        </inertial>
    </link>

    <link name="wheel_left">
        <visual>
            <geometry>
                <cylinder length="0.06" radius="0.1" />
            </geometry>
            
            <material name="uom_purple">
            <!-- Define a colour for the link -->
                <color rgba="0.4 0 0.6 1"/>
            </material>
            <origin xyz="0 0 0.03" rpy="0 0 0"/>
        </visual>
    </link>

    <link name="wheel_right">
        <visual>
            <geometry>
                <cylinder length="0.06" radius="0.1" />
            </geometry>

            <material name="uom_purple">
                <!-- Define a colour for the link -->
                <color rgba="0.4 0 0.6 1"/>
            </material>
            <origin xyz="0 0 -0.03" rpy="0 0 0"/>
        </visual>
    </link>

    <link name="castor_link">
        <visual>
            <geometry>
                <sphere radius="0.05"/>
            </geometry>

            <material name="red">
                <color rgba="1 0 0 1"/>
            </material>

            <origin xyz="0 0 0" rpy="0 0 0"/>
        </visual>

        <collision>
            <geometry>
                <sphere radius="0.05"/>
            </geometry>

            <origin xyz="0 0 0" rpy="0 0 0"/>
        </collision>
    </link>

    <link name="manipulator_1_link">
        <visual>
            <geometry>
                <cylinder length="0.5" radius="0.2"/>
            </geometry>
        
            <material name="manchester_yellow">
                <color rgba="1 0.9 0.2 1"/>
            </material>

            <origin xyz="0 0 0.25" rpy="0 0 0"/>

        </visual>
    </link>

    <link name="manipulator_2_link">
        <visual>
            <geometry>
                <cylinder length="0.5" radius="0.2"/>
            </geometry>
        
            <material name="manchester_yellow">
                <color rgba="1 0.9 0.2 1"/>
            </material>

            <origin xyz="0 0 0.5" rpy="0 0 0"/>

        </visual>
    </link>


    <!-- JOINTS -->
    <joint name="base_manipulator_joint" type="revolute">
        <parent link="base_link"/>
        <child link="manipulator_1_link"/>
        <origin xyz="0 0 0.3" rpy="0 0 0"/>

        <limit lower="-0.3927" upper="0.3927" effort="30" velocity="1.0"/>

        <axis xyz="0 0 1"/>
    </joint>

    <joint name="manipulator_manipulator_joint" type="revolute">
        <parent link="manipulator_1_link"/>
        <child link="manipulator_2_link"/>
        <origin xyz="0 0 0.25" rpy="0 0 0"/>

        <limit lower="-0.3927" upper="0.3927" effort="30" velocity="1.0"/>

        <axis xyz="0 1 0"/>
    </joint>

    <joint name="base_wheel_left_joint" type="continuous">
        <parent link="base_link"/>
        <child link="wheel_left"/>
        <origin xyz="0 0.2 0" rpy="-1.5707 0 0"/>
        <axis xyz="0 0 1"/>
    </joint>

    <joint name="base_wheel_right_joint" type="continuous">
        <parent link="base_link"/>
        <child link="wheel_right"/>
        <origin xyz="0 -0.2 0" rpy="-1.5707 0 0"/>
        <axis xyz="0 0 1"/>
    </joint>

    <joint name="castor_wheel_joint" type="fixed">
        <parent link="base_link"/>
        <child link="castor_link"/>
        <origin xyz="0.2 0 -0.05" rpy="0 0 0"/>
        <axis xyz="0 0 0"/>
    </joint>

</robot>
